<?xml version="1.0" ?>
<sdf version="1.4">
  <model name="bot_agv3">
    <pose>0.0 0.0 0.0 0.0 0.0 0.0</pose>

    <link name="base_footprint"/>

    <link name="base_link">

      <inertial>
        <pose>0.27563 0.56281 0.7922 0 0 0</pose>
        <inertial>
          <ixx>9.2282</ixx>
          <ixy>3.3569E-05</ixy>
          <ixz>7.603E-15</ixz>
          <iyy>22.081</iyy>
          <iyz>-8.5315E-17</iyz>
          <izz>13.953</izz>
        </inertial>
      </inertial>

      <collision name='base_link_collision'>
        <pose>0 0 0 0 0 0</pose>
        <geometry>
          <mesh>
            <uri>model://bot_agv/meshes/base_link.STL</uri>
          </mesh>
        </geometry>
        <surface>
          <contact>
            <ode/>
          </contact>
          <friction>
            <ode/>
          </friction>
        </surface>
      </collision>

      <visual name='base_link_visual'>
        <pose>-0.3 0.8 -0.5 0 0 0</pose>
        <geometry>
          <mesh>
            <uri>model://bot_agv/meshes/base_link.STL</uri>
          </mesh>
        </geometry>
        <material>
          <script>
            <name>Gazebo/White</name>
            <uri>file://media/materials/scripts/gazebo.material</uri>
          </script>
        </material>
      </visual>

      <visual name='box_link_visual'>
        <pose>-0.1 0.0078 0.16386 0 0 -3.1416</pose>
        <geometry>
          <mesh>
            <scale>1 1 1</scale>
            <uri>model://bot_agv/meshes/box_link.STL</uri>
          </mesh>
        </geometry>
        <material>
          <script>
            <name>Gazebo/White</name>
            <uri>file://media/materials/scripts/gazebo.material</uri>
          </script>
        </material>
      </visual>


  </link> 

    <link name="imu_link">
      <sensor name="agv_imu" type="imu">
        <always_on>true</always_on>
        <update_rate>200</update_rate>
        <imu>
          <angular_velocity>
            <x>
              <noise type="gaussian">
                <mean>0.0</mean>
                <stddev>2e-4</stddev>
              </noise>
            </x>
            <y>
              <noise type="gaussian">
                <mean>0.0</mean>
                <stddev>2e-4</stddev>
              </noise>
            </y>
            <z>
              <noise type="gaussian">
                <mean>0.0</mean>
                <stddev>2e-4</stddev>
              </noise>
            </z>
          </angular_velocity>
          <linear_acceleration>
            <x>
              <noise type="gaussian">
                <mean>0.0</mean>
                <stddev>1.7e-2</stddev>
              </noise>
            </x>
            <y>
              <noise type="gaussian">
                <mean>0.0</mean>
                <stddev>1.7e-2</stddev>
              </noise>
            </y>
            <z>
              <noise type="gaussian">
                <mean>0.0</mean>
                <stddev>1.7e-2</stddev>
              </noise>
            </z>
          </linear_acceleration>
        </imu>
        <plugin name="bot_imu" filename="libgazebo_ros_imu_sensor.so">
          <ros>
            <!-- <namespace>/agv</namespace> -->
            <remapping>~/out:=imu</remapping>
          </ros>
        </plugin>
      </sensor>
    </link>

    <link name="laser_link">
      <inertial>
        <pose>-0.020 0 0.161 0 0 0</pose>
        <inertia>
          <ixx>0.001</ixx>
          <ixy>0.000</ixy>
          <ixz>0.000</ixz>
          <iyy>0.001</iyy>
          <iyz>0.000</iyz>
          <izz>0.001</izz>
        </inertia>
        <mass>0.114</mass>
      </inertial>

      <collision name="laser_sensor_collision">
        <pose>0.37369 0.0078 1.72 0 0 0</pose>
        <geometry>
          <cylinder>
            <radius>0.0508</radius>
            <length>0.055</length>
          </cylinder>
        </geometry>
      </collision>

      <visual name="laser_sensor_visual">
        <pose>0.37369 0.0078 1.72 0 0 0</pose>
        <geometry>
          <mesh>
            <uri>model://turtlebot3_common/meshes/lds.dae</uri>
            <scale>0.001 0.001 0.001</scale>
          </mesh>
        </geometry>
      </visual>

      <sensor name="lslidar_C16" type="ray">
        <always_on>true</always_on>
        <visualize>false</visualize>
        <pose>0.37369 0.0078 1.722 0 0 0</pose>
        <update_rate>10</update_rate>
        <ray>
          <scan>
            <horizontal>
              <samples>360</samples>
              <resolution>0.200000</resolution>
              <min_angle>0.000000</min_angle>
              <max_angle>6.280000</max_angle>
            </horizontal>
          </scan>
          <vertical>
            <samples>30</samples>
            <resolution>2.0</resolution>
            <min_angle>-0.261799</min_angle> <!-- -15 degrees in radians -->
            <max_angle>0.261799</max_angle>  <!-- 15 degrees in radians -->
          </vertical>
          <range>
            <min>0.300000</min>
            <max>150.00</max>
            <resolution>0.02000</resolution>
          </range>
          <noise>
            <type>gaussian</type>
            <mean>0.0</mean>
            <stddev>0.01</stddev>
          </noise>
        </ray>
        <plugin name="agv_laserscan" filename="libgazebo_ros_ray_sensor.so">
          <ros>
            <!--namespace>/agv</namespace-->
            <remapping>~/out:=scan</remapping>
          </ros>
          <output_type>sensor_msgs/LaserScan</output_type>
          <frame_name>laser_link</frame_name>
        </plugin>
      </sensor>
    </link>

    <link name="laser">
      <inertial>
        <pose>-0.020 0 0.161 0 0 0</pose>
        <inertia>
          <ixx>0.001</ixx>
          <ixy>0.000</ixy>
          <ixz>0.000</ixz>
          <iyy>0.001</iyy>
          <iyz>0.000</iyz>
          <izz>0.001</izz>
        </inertia>
        <mass>0.114</mass>
      </inertial>

      <collision name="laser_collision">
        <pose>0.37369 0.0078 0.18386 0 0 0</pose>
        <geometry>
          <cylinder>
            <radius>0.0508</radius>
            <length>0.055</length>
          </cylinder>
        </geometry>
      </collision>

      <visual name="laser_visual">
        <pose>0.37369 0.0078 0.18386 0 0 0</pose>
        <geometry>
          <mesh>
            <uri>model://turtlebot3_common/meshes/lds.dae</uri>
            <scale>0.001 0.001 0.001</scale>
          </mesh>
        </geometry>
      </visual>

      <sensor name="lidar" type="ray">
        <always_on>true</always_on>
        <visualize>false</visualize>
        <pose>0.37369 0.0078 0.17386 0 0 0</pose>
        <update_rate>5</update_rate>
        <ray>
          <scan>
            <horizontal>
              <samples>360</samples>
              <resolution>1.000000</resolution>
              <min_angle>0.0000</min_angle>
              <max_angle>6.280000</max_angle>
            </horizontal>
          </scan>
          <range>
            <min>0.20000</min>
            <max>25.0</max>
            <resolution>0.015000</resolution>
          </range>
          <noise>
            <type>gaussian</type>
            <mean>0.0</mean>
            <stddev>0.01</stddev>
          </noise>
        </ray>
        <plugin name="agv2_laserscan" filename="libgazebo_ros_ray_sensor.so">
          <ros>
            <!--namespace>/agv</namespace-->
            <remapping>~/out:=scan</remapping>
          </ros>
          <output_type>sensor_msgs/LaserScan</output_type>
          <frame_name>laser</frame_name>
        </plugin>
      </sensor>
    </link>

    <link name="wheel_left_link">

      <inertial>
        <pose>-0 0 0.05 0 -0 0</pose>
        <mass>3.0709</mass>
        <inertia>
          <ixx>0.010409</ixx>
          <ixy>-6.074e-38</ixy>
          <ixz>3.7616e-35</ixz>
          <iyy>0.010409</iyy>
          <iyz>-3.1038e-35</iyz>
          <izz>0.0157</izz>
        </inertia>
      </inertial>

      <collision name="wheel_left_collision">
        <pose>-0.02436 0.4328 0.04396 1.5708 0 0</pose>
        <geometry>
          <mesh>
            <scale>1 1 1</scale>
            <uri>model://bot_agv/meshes/wheel_first.STL</uri>
          </mesh>
        </geometry>
        <surface>
          <!-- This friction pamareter don't contain reliable data!! -->
          <friction>
            <ode>
              <mu>100000.0</mu>
              <mu2>100000.0</mu2>
              <fdir1>0 0 0</fdir1>
              <slip1>0.0</slip1>
              <slip2>0.0</slip2>
            </ode>
          </friction>
          <contact>
            <ode>
              <soft_cfm>0</soft_cfm>
              <soft_erp>0.2</soft_erp>
              <kp>1e+5</kp>
              <kd>1</kd>
              <max_vel>0.01</max_vel>
              <min_depth>0.001</min_depth>
            </ode>
          </contact>
        </surface>
      </collision>

      <visual name="wheel_left_visual">
        <pose>-0.02436 0.4328 0.04396 1.5708 0 0</pose>
        <geometry>
          <mesh>
            <scale>1 1 1</scale>
            <uri>model://bot_agv/meshes/wheel_first.STL</uri>
          </mesh>
        </geometry>
        <material>
          <script>
            <name>Gazebo/Blue</name>
            <uri>file://media/materials/scripts/gazebo.material</uri>
          </script>
        </material>
      </visual>
    </link>

    <link name="wheel_right_link">

      <inertial>
        <pose>0 -0 0.05 0 -0 0</pose>
        <mass>3.0709</mass>
        <inertia>
          <ixx>0.010409</ixx>
          <ixy>-6.074e-38</ixy>
          <ixz>4.4417e-37</ixz>
          <iyy>0.010409</iyy>
          <iyz>-3.1038e-35</iyz>
          <izz>0.0157</izz>
        </inertia>
      </inertial>

      <collision name="wheel_right_collision">
        <pose>-0.02436 -0.3172 0.04396 1.5708 0 0</pose>
        <geometry>
          <mesh>
            <scale>1 1 1</scale>
            <uri>model://bot_agv/meshes/wheel_second.STL</uri>
          </mesh>
        </geometry>
        <surface>
          <!-- This friction pamareter don't contain reliable data!! -->
          <friction>
            <ode>
              <mu>100000.0</mu>
              <mu2>100000.0</mu2>
              <fdir1>0 0 0</fdir1>
              <slip1>0.0</slip1>
              <slip2>0.0</slip2>
            </ode>
          </friction>
          <contact>
            <ode>
              <soft_cfm>0</soft_cfm>
              <soft_erp>0.2</soft_erp>
              <kp>1e+5</kp>
              <kd>1</kd>
              <max_vel>0.01</max_vel>
              <min_depth>0.001</min_depth>
            </ode>
          </contact>
        </surface>
      </collision>

      <visual name="wheel_right_visual">
        <pose>-0.02436 -0.3172 0.04396 1.5708 0 0</pose>
        <geometry>
          <mesh>
            <scale>1 1 1</scale>
            <uri>model://bot_agv/meshes/wheel_second.STL</uri>
          </mesh>
        </geometry>
        <material>
          <script>
            <name>Gazebo/Blue</name>
            <uri>file://media/materials/scripts/gazebo.material</uri>
          </script>
        </material>
      </visual>
    </link>

    <link name='wheel_back_right_link'>
      <pose>0.37369 0.0078 -0.0506 0 0 0</pose>
      <inertial>
        <mass>0.005</mass>
        <inertia>
          <ixx>0.001</ixx>
          <ixy>0.000</ixy>
          <ixz>0.000</ixz>
          <iyy>0.001</iyy>
          <iyz>0.000</iyz>
          <izz>0.001</izz>
        </inertia>
      </inertial>
      <collision name='collision'>
        <geometry>
          <sphere>
            <radius>0.005000</radius>
          </sphere>
        </geometry>
        <surface>
          <contact>
            <ode>
              <soft_cfm>0</soft_cfm>
              <soft_erp>0.2</soft_erp>
              <kp>1e+5</kp>
              <kd>1</kd>
              <max_vel>0.01</max_vel>
              <min_depth>0.001</min_depth>
            </ode>
          </contact>
        </surface>
      </collision>
    </link>

    <link name='wheel_back_left_link'>
      <pose>-0.37369 0.0078 -0.0506 0 0 0</pose>
      <inertial>
        <mass>0.005</mass>
        <inertia>
          <ixx>0.001</ixx>
          <ixy>0.000</ixy>
          <ixz>0.000</ixz>
          <iyy>0.001</iyy>
          <iyz>0.000</iyz>
          <izz>0.001</izz>
        </inertia>
      </inertial>
      <collision name='collision'>
        <geometry>
          <sphere>
            <radius>0.005000</radius>
          </sphere>
        </geometry>
        <surface>
          <contact>
            <ode>
              <soft_cfm>0</soft_cfm>
              <soft_erp>0.2</soft_erp>
              <kp>1e+5</kp>
              <kd>1</kd>
              <max_vel>0.01</max_vel>
              <min_depth>0.001</min_depth>
            </ode>
          </contact>
        </surface>
      </collision>
    </link>

    <joint name='base_joint' type='fixed'>
      <pose relative_to='base_footprint'>0 0 0 0 0 0</pose>
      <parent>base_footprint</parent>
      <child>base_link</child>
    </joint>    

    <joint name="wheel_left_joint" type="revolute">
      <parent>base_link</parent>
      <child>wheel_left_link</child>
      <pose>-0.02436 0.4328 0.04396 1.5708 0 0</pose>
      <axis>
        <xyz>0 1 0</xyz>
      </axis>
    </joint>

    <joint name="wheel_right_joint" type="revolute">
      <parent>base_link</parent>
      <child>wheel_right_link</child>
      <pose>-0.02436 -0.3172 0.04396 1.5708 0 0</pose>
      <axis>
        <xyz>0 1 0</xyz>
      </axis>
    </joint>

    <joint name='wheel_back_right_joint' type='ball'>
      <parent>base_link</parent>
      <child>wheel_back_right_link</child>
    </joint>

    <joint name='wheel_back_left_joint' type='ball'>
      <parent>base_link</parent>
      <child>wheel_back_left_link</child>
    </joint>

    <joint name="imu_joint" type="fixed">
      <pose relative_to="base_link">0.17369 0.0078 0.16386 0 0 0</pose>
       <parent>base_link</parent>
       <child>imu_link</child>
     <axis>
      <xyz>0 0 1</xyz>
     </axis>
   </joint>

    <joint name="laser_joint" type="fixed">
      <pose relative_to='base_link'>0.37369 0.0078 1.72 0 0 0</pose>
      <parent>base_link</parent>
      <child>laser_link</child>
      <axis>
        <xyz>0 0 1</xyz>
      </axis>
    </joint>

    <joint name="laser1_joint" type="fixed">
      <pose relative_to='base_link'>0.37369 0.0078 0.18386 0 0 0</pose>
      <parent>base_link</parent>
      <child>laser</child>
      <axis>
        <xyz>0 0 1</xyz>
      </axis>
    </joint>

    <plugin name="agv_diff_drive" filename="libgazebo_ros_diff_drive.so">

      <ros>
        <!-- <namespace>/agv</namespace> -->
      </ros>

      <update_rate>30</update_rate>

      <!-- wheels -->
      <left_joint>wheel_left_joint</left_joint>
      <right_joint>wheel_right_joint</right_joint>

      <!-- kinematics -->
      <wheel_separation>0.65</wheel_separation>
      <wheel_diameter>0.1</wheel_diameter>

      <!-- limits -->
      <max_wheel_torque>20</max_wheel_torque>
      <max_wheel_acceleration>1.0</max_wheel_acceleration>

      <command_topic>cmd_vel</command_topic>

      <!-- output -->
      <publish_odom>true</publish_odom>
      <publish_odom_tf>true</publish_odom_tf>
      <publish_wheel_tf>false</publish_wheel_tf>

      <odometry_topic>odom</odometry_topic>
      <odometry_frame>odom</odometry_frame>
      <robot_base_frame>base_footprint</robot_base_frame>

    </plugin>

    <plugin name="agv_joint_state" filename="libgazebo_ros_joint_state_publisher.so">
      <ros>
        <!-- <namespace>/agv</namespace> -->
        <remapping>~/out:=joint_states</remapping>
      </ros>
      <update_rate>30</update_rate>
      <joint_name>wheel_left_joint</joint_name>
      <joint_name>wheel_right_joint</joint_name>
    </plugin>      
  </model>
</sdf>
