<?xml version="1.0" ?>
<sdf version="1.4">
  <model name="bot_agv5">
     
        <link name="base_footprint"/>
    
        <joint name="base_joint" type="fixed">
          <parent>base_footprint</parent>
          <child>base_link</child>
          <pose>0 0 0 0 0 0</pose>
        </joint>
    
        <link name="base_link">
          <pose>0 0 0 0 0 0</pose>
          <inertial>
            <mass>288.88</mass>
            <pose>0.44897 0.83959 0.84573 0 0 0</pose>
            <inertia>
              <ixx>44.848</ixx>
              <ixy>-0.16219</ixy>
              <ixz>0.0078397</ixz>
              <iyy>53.3</iyy>
              <iyz>-0.0015458</iyz>
              <izz>49.091</izz>
            </inertia>
          </inertial>
          <collision>
            <pose>0 0 0 0 0 0</pose>
            <geometry>
              <mesh>
              <scale>1 1 1</scale>
              <uri>model://bot_agv5/meshes/base_link.STL</uri></mesh>
            </geometry>
          </collision>
          <visual>
            <pose>0 0 0 0 0 0</pose>
            <geometry>
              <mesh>
                <scale>1 1 1</scale>
                <uri>model://bot_agv5/meshes/base_link.STL</uri></mesh>
            </geometry>
            <material>
              <ambient>0.79216 0.81961 0.93333 1</ambient>
            </material>
          </visual>
        </link>
    
        <link name="laser">
          <inertial>
            <mass>0.16307</mass>
            <pose>0.00025711 -0.019085 -0.00093411 0 0 0</pose>
            <inertia>
              <ixx>6.0437E-05</ixx>
              <ixy>-6.5608E-08</ixy>
              <ixz>-1.1037E-07</ixz>
              <iyy>0.00010759</iyy>
              <iyz>2.3216E-07</iyz>
              <izz>6.0727E-05</izz>
            </inertia>
          </inertial>
          <collision>
            <pose>0.44756 -0.84551 0.5627 0 0 0</pose>
            <geometry>
              <mesh>
                <scale>1 1 1</scale>
                <uri>model://bot_agv5/meshes/laser.STL</uri></mesh>
            </geometry>
          </collision>
          <visual>
            <pose>0.44756 -0.84551 0.5627 0 0 0</pose>
            <geometry>
              <mesh>
                <scale>1 1 1</scale>
                <uri>model://bot_agv5/meshes/laser.STL</uri></mesh>
            </geometry>
            <material>
              <ambient>0.79216 0.81961 0.93333 1</ambient>
            </material>
          </visual>
        </link>
    
        <joint name="rplidar_joint" type="fixed">
          <parent>base_link</parent>
          <child>laser</child>
          <pose>0.44756 -0.84551 0.5627 0 0 0</pose>
        </joint>
    
        <link name="laser_link">
          <inertial>
            <mass>0.60561</mass>
            <pose>0.00010213 0.036297 3.2869E-06 0 0 0</pose>
            <inertia>
              <ixx>0.00066704</ixx>
              <ixy>1.8129E-06</ixy>
              <ixz>1.7526E-11</ixz>
              <iyy>0.00080407</iyy>
              <iyz>6.6764E-08</iyz>
              <izz>0.00067092</izz>
            </inertia>
          </inertial>
          <collision>
            <pose>1.009 -0.84566 2.0197 1.5708 0 3.1416</pose>
            <geometry>
              <mesh>
                <scale>1 1 1</scale>
                <uri>model://bot_agv5/meshes/laser_link.STL</uri></mesh>
            </geometry>
          </collision>
          <visual>
            <pose>1.009 -0.84566 2.0197 1.5708 0 3.1416</pose>
            <geometry>
              <mesh>
                <scale>1 1 1</scale>
                <uri>model://bot_agv5/meshes/laser_link.STL</uri></mesh>
            </geometry>
            <material>
              <ambient>0.79216 0.81961 0.93333 1</ambient>
            </material>
          </visual>
        </link>
    
        <joint name="lslidar_joint" type="fixed">
          <parent>base_link</parent>
          <child>laser_link</child>
          <pose>1.009 -0.84566 2.0197 0 0 0</pose>
        </joint>
    
        <link name="wheel_left_link">
          <inertial>
            <mass>2.9679</mass>
            <pose>0 0 0.05 0 0 0</pose>
            <inertia>
              <ixx>0.0097224</ixx>
              <ixy>-2.1684E-19</ixy>
              <ixz>-1.6122E-19</ixz>
              <iyy>0.0097224</iyy>
              <iyz>1.7156E-20</iyz>
              <izz>0.014755</izz>
            </inertia>
          </inertial>
          <collision>
            <pose>0.44771 -1.1482 0.4297 -1.5708 0.21783 -3.1416</pose>
            <geometry>
              <mesh>
                <scale>1 1 1</scale>
                <uri>model://bot_agv5/meshes/wheel_left_link.STL</uri></mesh>
            </geometry>
          </collision>
          <visual>
            <pose>0.44771 -1.1482 0.4297 -1.5708 0.21783 -3.1416</pose>
            <geometry>
              <mesh>
                <scale>1 1 1</scale>
                <uri>model://bot_agv5/meshes/wheel_left_link.STL</uri></mesh>
            </geometry>
            <material>
              <ambient>0.79216 0.81961 0.93333 1</ambient>
            </material>
          </visual>
        </link>
    
        <joint name="wheel_left_joint" type="continuous">
          <parent>base_link</parent>
          <child>wheel_left_link</child>
          <pose>0.44771 -1.1482 0.4297 0 0 0</pose>
          <axis>
            <xyz>0 0 1</xyz>
            <limit>
              <effort>10.0</effort>
              <velocity>0.5</velocity>
            </limit>
          </axis>
        </joint>
    
        <link name="wheel_right_link">
          <inertial>
            <mass>2.9679</mass>
            <pose>5.5511E-17 -5.5511E-17 0.05 0 0 0</pose>
            <inertia>
              <ixx>0.0097224</ixx>
              <ixy>-6.074E-38</ixy>
              <ixz>0</ixz>
              <iyy>0.0097224</iyy>
              <iyz>-1.6088E-35</iyz>
              <izz>0.014755</izz>
            </inertia>
          </inertial>
          <collision>
            <pose>0.44771 -0.44316 0.4297 1.5708 0 0</pose>
            <geometry>
              <mesh>
                <scale>1 1 1</scale>
                <uri>model://bot_agv5/meshes/wheel_right_link.STL</uri></mesh>
            </geometry>
          </collision>
          <visual>
            <pose>0.44771 -0.44316 0.4297 1.5708 0 0</pose>
            <geometry>
              <scale>1 1 1</scale>
              <mesh><uri>package://host_agv/models/bot_agv5/meshes/wheel_right_link.STL</uri></mesh>
            </geometry>
            <material>
              <ambient>0.79216 0.81961 0.93333 1</ambient>
            </material>
          </visual>
        </link>
    
        <joint name="wheel_right_joint" type="continuous">
          <parent>base_link</parent>
          <child>wheel_right_link</child>
          <pose>0.44771 -0.44316 0.4297 0 0 0</pose>
          <axis>
            <xyz>0 0 1</xyz>
            <limit>
              <effort>10.0</effort>
              <velocity>0.5</velocity>
            </limit>
          </axis>
        </joint>
      
        <link name="imu_link">
          <inertial>
            <pose>-0.0184 0.0275 -0.012 0 0 0</pose>
            <mass>0.048576</mass>
            <inertia>
              <ixx>1.4577E-05</ixx>
              <ixy>3.3007E-20</ixy>
              <ixz>-2.8462E-20</ixz>
              <iyy>7.8136E-06</iyy>
              <iyz>2.1514E-19</iyz>
              <izz>1.7727E-05</izz>
            </inertia>
          </inertial>
          <visual>
            <pose>0.010212 -0.61726 0.5147 -3.1416 0 1.5708</pose>
            <geometry>
              <mesh>
                <scale>1 1 1</scale>
                <uri>model://bot_agv5/meshes/imu_link.STL</uri></mesh>
            </geometry>
            <material>
              <ambient>0.79216 0.81961 0.93333 1</ambient>
            </material>
          </visual>
          <collision>
            <pose>0.010212 -0.61726 0.5147 -3.1416 0 1.5708</pose>
            <geometry>
              <mesh>
                <scale>1 1 1</scale>
                <uri>model://bot_agv5/meshes/imu_link.STL</uri></mesh>
            </geometry>
          </collision>
        </link>
    
        <!-- Joint connecting base_link to imu_link -->
        <joint name="imu_joint" type="fixed">
          <pose>0.010212 -0.61726 0.5147 -3.1416 0 1.5708</pose>
          <parent>base_link</parent>
          <child>imu_link</child>
          <axis>
            <xyz>0 0 0</xyz>
          </axis>
        </joint>
    
        <!-- Camera link -->
        <link name="camera_link">
          <inertial>
            <pose>1.1443E-05 -0.00013623 0.011556 0 0 0</pose>
            <mass>0.10791</mass>
            <inertia>
              <ixx>7.7099E-06</ixx>
              <ixy>-2.7921E-10</ixy>
              <ixz>-1.7968E-08</ixz>
              <iyy>7.0256E-05</iyy>
              <iyz>4.9369E-08</iyz>
              <izz>7.1254E-05</izz>
            </inertia>
          </inertial>
          <visual>
            <pose>0.91315 -0.84578 0.49895 1.4667 0 1.5708</pose>
            <geometry>
              <mesh>
                <scale>1 1 1</scale>
                <uri>model://bot_agv5/meshes/camera_link.STL</uri></mesh>
            </geometry>
            <material>
              <ambient>0.89804 0.91765 0.92941 1</ambient>
            </material>
          </visual>
          <collision>
            <pose>0.91315 -0.84578 0.49895 1.4667 0 1.5708</pose>
            <geometry>
              <mesh>
                <scale>1 1 1</scale>
                <uri>model://bot_agv5/meshes/camera_link.STL</uri></mesh>
            </geometry>
          </collision>
        </link>
    
        <!-- Joint connecting base_link to camera_link -->
        <joint name="camera_joint" type="fixed">
          <pose>0.91315 -0.84578 0.49895 1.4667 0 1.5708</pose>
          <parent>base_link</parent>
          <child>camera_link</child>
          <axis>
            <xyz>0 0 0</xyz>
          </axis>
        </joint>

<!-- Sensor one link -->
<link name="sensor_one">
  <pose>-0.011509 -7.9086E-05 0.014139 0 0 0</pose>
  <inertial>
    <pose>0 0 0 0 0 0</pose>
    <mass>0.0062193</mass>
    <inertia>
      <ixx>2.1694E-07</ixx>
      <ixy>1.2249E-09</ixy>
      <ixz>-5.1946E-14</ixz>
      <iyy>9.8554E-07</iyy>
      <iyz>2.2269E-09</iyz>
      <izz>1.0096E-06</izz>
    </inertia>
  </inertial>
  <visual>
    <pose>0.95093 -0.83366 0.4072 1.5708 0 1.5708</pose>
    <geometry>
      <mesh>
        <scale>1 1 1</scale>
        <uri>model://bot_agv5/meshes/sensor_one.STL</uri>
      </mesh>
    </geometry>
    <material>
      <ambient>0.29804 0.29804 0.29804 1</ambient>
    </material>
  </visual>
  <collision>
    <pose>0.95093 -0.83366 0.4072 1.5708 0 1.5708</pose>
    <geometry>
      <mesh>
        <scale>1 1 1</scale>
        <uri>model://bot_agv5/meshes/sensor_one.STL</uri>
      </mesh>
    </geometry>
  </collision>
</link>

<!-- Joint connecting base_link to sensor_one -->
<joint name="front_one_joint" type="fixed">
  <parent>base_link</parent>
  <child>sensor_one</child>
  <pose>0.95093 -0.83366 0.4072 1.5708 0 1.5708</pose>
</joint>

<!-- Sensor two link -->
<link name="sensor_two">
  <pose>-8.5525E-06 -7.9086E-05 0.0043485 0 0 0</pose>
  <inertial>
    <pose>0 0 0 0 0 0</pose>
    <mass>0.0062193</mass>
    <inertia>
      <ixx>2.1694E-07</ixx>
      <ixy>1.2249E-09</ixy>
      <ixz>-5.1688E-14</ixz>
      <iyy>9.8554E-07</iyy>
      <iyz>2.2269E-09</iyz>
      <izz>1.0096E-06</izz>
    </inertia>
  </inertial>
  <visual>
    <pose>0.94019 -1.1492 0.4573 1.5708 0 1.3198</pose>
    <geometry>
      <mesh>
        <scale>1 1 1</scale>
        <uri>model://bot_agv5/meshes/sensor_two.STL</uri>
      </mesh>
    </geometry>
    <material>
      <ambient>0.29804 0.29804 0.29804 1</ambient>
    </material>
  </visual>
  <collision>
    <pose>0.94019 -1.1492 0.4573 1.5708 0 1.3198</pose>
    <geometry>
      <mesh>
        <scale>1 1 1</scale>
        <uri>model://bot_agv5/meshes/sensor_two.STL</uri>
      </mesh>
    </geometry>
  </collision>
</link>

<!-- Joint connecting base_link to sensor_two -->
<joint name="front_two_joint" type="fixed">
  <parent>base_link</parent>
  <child>sensor_two</child>
  <pose>0.94019 -1.1492 0.4573 1.5708 0 1.3198</pose>
</joint>

<!-- Sensor three link -->
<link name="sensor_three">
  <pose>0.011491 -7.9086E-05 0.012794 0 0 0</pose>
  <inertial>
    <pose>0 0 0 0 0 0</pose>
    <mass>0.0062193</mass>
    <inertia>
      <ixx>2.1694E-07</ixx>
      <ixy>1.2249E-09</ixy>
      <ixz>-5.341E-14</ixz>
      <iyy>9.8554E-07</iyy>
      <iyz>2.2269E-09</iyz>
      <izz>1.0096E-06</izz>
    </inertia>
  </inertial>
  <visual>
    <pose>0.93474 -0.5549 0.4572 1.5708 0 1.8218</pose>
    <geometry>
      <mesh>
        <scale>1 1 1</scale>
        <uri>model://bot_agv5/meshes/sensor_three.STL</uri>
      </mesh>
    </geometry>
    <material>
      <ambient>0.29804 0.29804 0.29804 1</ambient>
    </material>
  </visual>
  <collision>
    <pose>0.93474 -0.5549 0.4572 1.5708 0 1.8218</pose>
    <geometry>
      <mesh>
        <scale>1 1 1</scale>
        <uri>model://bot_agv5/meshes/sensor_three.STL</uri>
      </mesh>
    </geometry>
  </collision>
</link>

<!-- Joint connecting base_link to sensor_three -->
<joint name="front_three_joint" type="fixed">
  <parent>base_link</parent>
  <child>sensor_three</child>
  <pose>0.93474 -0.5549 0.4572 1.5708 0 1.8218</pose>
</joint>

<!-- Sensor four link -->
<link name="sensor_four">
  <pose>0.011491 7.9086E-05 -0.014139 0 0 0</pose>
  <inertial>
    <pose>0 0 0 0 0 0</pose>
    <mass>0.0062193</mass>
    <inertia>
      <ixx>2.1694E-07</ixx>
      <ixy>-1.2249E-09</ixy>
      <ixz>5.1946E-14</ixz>
      <iyy>9.8554E-07</iyy>
      <iyz>2.2269E-09</iyz>
      <izz>1.0096E-06</izz>
    </inertia>
  </inertial>
  <visual>
    <pose>-0.055584 -0.83366 0.4072 -1.5708 0 -1.5708</pose>
    <geometry>
      <mesh>
        <scale>1 1 1</scale>
        <uri>model://bot_agv5/meshes/sensor_four.STL</uri>
      </mesh>
    </geometry>
    <material>
      <ambient>0.29804 0.29804 0.29804 1</ambient>
    </material>
  </visual>
  <collision>
    <pose>-0.055584 -0.83366 0.4072 -1.5708 0 -1.5708</pose>
    <geometry>
      <mesh>
        <scale>1 1 1</scale>
        <uri>model://bot_agv5/meshes/sensor_four.STL</uri>
      </mesh>
    </geometry>
  </collision>
</link>

<!-- Joint connecting base_link to sensor_four -->
<joint name="back_four_joint" type="fixed">
  <parent>base_link</parent>
  <child>sensor_four</child>
  <pose>-0.055584 -0.83366 0.4072 -1.5708 0 -1.5708</pose>
</joint>

<!-- Sensor five link -->
<link name="sensor_five">
  <pose>-8.5525E-06 -7.9086E-05 0.0043485 0 0 0</pose>
  <inertial>
    <pose>0 0 0 0 0 0</pose>
    <mass>0.0062193</mass>
    <inertia>
      <ixx>2.1694E-07</ixx>
      <ixy>1.2249E-09</ixy>
      <ixz>-5.1688E-14</ixz>
      <iyy>9.8554E-07</iyy>
      <iyz>2.2269E-09</iyz>
      <izz>1.0096E-06</izz>
    </inertia>
  </inertial>

  <visual>
    <pose>-0.044519 -0.54117 0.4572 1.5708 0 -1.8218</pose>
    <geometry>
      <mesh>
        <scale>1 1 1</scale>
        <uri>model://bot_agv5/meshes/sensor_five.STL</uri>
      </mesh>
    </geometry>
    <material>
      <ambient>0.29804 0.29804 0.29804 1</ambient>
    </material>
  </visual>
  <collision>
    <pose>-0.044519 -0.54117 0.4572 1.5708 0 -1.8218</pose>
    <geometry>
      <mesh>
        <scale>1 1 1</scale>
        <uri>model://bot_agv5/meshes/sensor_five.STL</uri>
      </mesh>
    </geometry>
  </collision>
</link>

<!-- Joint connecting base_link to sensor_five -->
<joint name="back_five_joint" type="fixed">
  <parent>base_link</parent>
  <child>sensor_five</child>
  <pose>-0.044519 -0.54117 0.4572 1.5708 0 -1.8218</pose>
</joint>

<!-- Sensor six link -->
<link name="sensor_six">
  <pose>0 0 0 0 0 0</pose>
  <inertial>
    <pose>0 0 0 0 0 0</pose>
    <mass>0</mass>
    <inertia>
      <ixx>0</ixx>
      <ixy>0</ixy>
      <ixz>0</ixz>
      <iyy>0</iyy>
      <iyz>0</iyz>
      <izz>0</izz>
    </inertia>
  </inertial>
  <visual>
    <pose>-0.044519 -1.1501 0.4572 1.5708 0 -1.3198</pose>
    <geometry>
      <mesh>
        <scale>1 1 1</scale>
        <uri>model://bot_agv5/meshes/sensor_six.STL</uri>
      </mesh>
    </geometry>
    <material>
      <ambient>1 1 1 1</ambient>
    </material>
  </visual>
  <collision>
    <pose>-0.044519 -1.1501 0.4572 1.5708 0 -1.3198</pose>
    <geometry>
      <mesh>
        <scale>1 1 1</scale>
        <uri>model://bot_agv5/meshes/sensor_six.STL</uri>
      </mesh>
    </geometry>
  </collision>
</link>

<!-- Joint connecting base_link to sensor_six -->
<joint name="back_six_joint" type="fixed">
  <parent>base_link</parent>
  <child>sensor_six</child>
  <pose>-0.044519 -1.1501 0.4572 1.5708 0 -1.3198</pose>
</joint>


  </model>
</sdf>
