<?xml version="1.0" ?>
<robot name="bot_agv3" xmlns:xacro="http://ros.org/wiki/xacro">
<xacro:include filename="$(find host_agv)/models/common_properties.urdf"/>

  <link name="base_footprint"/>

  <joint name="base_joint" type="fixed">
    <parent link="base_footprint"/>
    <child link="base_link"/>
    <origin xyz="0.0 0.0 0.0" rpy="0 0 0"/>
  </joint>

  <link name="base_link">
    <inertial>
      <origin xyz="0.27563 0.56281 0.7922" rpy="0 0 0" />
      <mass value="158.95" />
      <inertia ixx="9.2282" ixy="3.3569E-05" ixz="7.603E-15"
               iyy="22.081" iyz="-8.5315E-17" izz="13.953" />
    </inertial>
  
    <visual>
      <origin xyz="-0.3 0.8 -0.5" rpy="0 0 0" />
      <geometry>
        <mesh filename="package://host_agv/meshes/base_link.STL" />
      </geometry>
      <material name="White">
        <color rgba="1 1 1 1" />
      </material>
    </visual>

    <visual>
      <origin xyz="-0.1 0.0078 0.16386" rpy="0 0 -3.1416" />
      <geometry>
        <mesh filename="package://host_agv/models/bot_agv/meshes/box_link.STL" />
      </geometry>
      <material name="White">
        <color rgba="1 1 1 1" />
      </material>
    </visual>
  
    <collision>
      <origin xyz="0 0 0" rpy="0 0 0" />
      <geometry>
        <mesh filename="package://host_agv/meshes/base_link.STL" />
      </geometry>
    </collision>
  </link>
  <gazebo reference="base_link">
    <material>Gazebo/Green</material>
  </gazebo>  

  <joint name="wheel_left_joint" type="continuous">
    <parent link="base_link"/>
    <child link="wheel_left_link"/>
    <origin xyz="-0.02436 0.4328 0.04396" rpy="1.5708 0 0" />
    <axis xyz="0 0 1"/>
  </joint>

  <link name="wheel_left_link">
    <visual>
      <origin xyz="0 0 0" rpy="0 0 0" />
      <geometry>
        <mesh filename="package://host_agv/meshes/wheel_first.STL" />
      </geometry>
      <material name="blue">
        <color rgba="0.5 0.2 1 1" />
      </material>
    </visual>

    <collision>
      <origin xyz="0 0 0" rpy="0 0 0" />
      <geometry>
        <mesh filename="package://host_agv/meshes/wheel_first.STL" />
      </geometry>
    </collision>

    <inertial>
      <origin xyz="-5.5511E-17 0 0.05" rpy="0 0 0" />
      <mass value="3.0709" />
      <inertia ixx="0.010409" ixy="-6.074E-38" ixz="3.7616E-35"
               iyy="0.010409" iyz="-3.1038E-35" izz="0.0157" />
    </inertial>
  </link>
  <gazebo reference="wheel_left_link">
    <material>Gazebo/Blue</material>
  </gazebo>

  <joint name="wheel_right_joint" type="continuous">
    <parent link="base_link"/>
    <child link="wheel_right_link"/>
    <origin xyz="-0.02436 -0.3172 0.04396" rpy="1.5708 0 0" />
    <axis xyz="0 0 1"/>
  </joint>

  <link name="wheel_right_link">
    <visual>
      <origin xyz="0 0 0" rpy="0 0 0" />
      <geometry>
        <mesh filename="package://host_agv/meshes/wheel_second.STL" />
      </geometry>
      <material name="">
        <color rgba="0.5 0.2 1 1" />
      </material>
    </visual>

    <collision>
      <origin xyz="0 0 0" rpy="0 0 0" />
      <geometry>
        <mesh filename="package://host_agv/meshes/wheel_second.STL" />
      </geometry>
    </collision>

    <inertial>
      <origin xyz="0 -1.1102E-16 0.05" rpy="0 0 0" />
      <mass value="3.0709" />
      <inertia ixx="0.010409" ixy="-6.074E-38" ixz="4.4417E-37"
               iyy="0.010409" iyz="-3.1038E-35" izz="0.0157" />
    </inertial>
  </link>
  <gazebo reference="wheel_right_link">
    <material>Gazebo/Blue</material>
  </gazebo>

  <joint name="wheel_back_left_joint" type="fixed">
    <parent link="base_link"/>
    <child link="wheel_back_left_link"/>
    <origin xyz="-0.37369 0.0078 -0.0506" rpy="0 0 0"/>
  </joint>

  <link name="wheel_back_left_link">
    <collision>
      <origin xyz="-0.37369 0.0078 -0.0506" rpy="0 0 0"/>
      <geometry>
        <box size="0.030 0.009 0.020"/>
      </geometry>
    </collision>

    <inertial>
      <origin xyz="0 0 0" />
      <mass value="0.005" />
      <inertia ixx="0.001" ixy="0.0" ixz="0.0" iyy="0.001" iyz="0.0" izz="0.001" />
    </inertial>
  </link>

  <joint name="wheel_back_right_joint" type="fixed">
    <parent link="base_link"/>
    <child link="wheel_back_right_link"/>
    <origin xyz="0.37369 0.0078 -0.0506" rpy="0 0 0"/>
  </joint>

  <link name="wheel_back_right_link">
    <collision>
      <origin xyz="0.37369 0.0078 -0.0506" rpy="0 0 0"/>
      <geometry>
        <box size="0.030 0.009 0.020"/>
      </geometry>
    </collision>

    <inertial>
      <origin xyz="0 0 0" />
      <mass value="0.005" />
      <inertia ixx="0.001" ixy="0.0" ixz="0.0" iyy="0.001" iyz="0.0" izz="0.001" />
    </inertial>
  </link>

  <joint name="imu_joint" type="fixed">
    <parent link="base_link"/>
    <child link="imu_link"/>
    <origin xyz="0.17369 0.0078 0.16386" rpy="0 0 0"/>
  </joint>

  <link name="imu_link"/>

  <joint name="laser_joint" type="fixed">
    <parent link="base_link"/>
    <child link="laser_link"/>
    <origin xyz="0.37369 0.0078 1.72" rpy="0 0 0"/>
  </joint>

  <link name="laser_link">
    <visual>
      <origin xyz="0 0 0" rpy="0 0 0"/>
      <geometry>
        <mesh filename="package://host_agv/models/turtlebot3_common/meshes/lds.dae" scale="0.001 0.001 0.001"/>
      </geometry>
      <material name="dark"/>
    </visual>
      <!-- Init colour -->

    <material name="dark">
    <color rgba="0.3 0.3 0.3 1.0"/>
    </material>

    <collision>
      <origin xyz="0.37369 0.0078 1.72" rpy="0 0 0"/>
      <geometry>
        <cylinder length="0.0315" radius="0.055"/>
      </geometry>
    </collision>

    <inertial>
      <mass value="0.114" />
      <origin xyz="0 0 0" />
      <inertia ixx="0.001" ixy="0.0" ixz="0.0" iyy="0.001" iyz="0.0" izz="0.001" />
    </inertial>
  </link>

  <joint name="laser1_joint" type="fixed">
    <parent link="base_link"/>
    <child link="laser"/>
    <origin xyz="0.37369 0.0078 0.18386" rpy="0 0 0"/>
  </joint>

  <link name="laser">
    <visual>
      <origin xyz="0 0 0" rpy="0 0 0"/>
      <geometry>
        <mesh filename="package://host_agv/models/turtlebot3_common/meshes/lds.dae" scale="0.001 0.001 0.001"/>
      </geometry>
      <material name="dark"/>
    </visual>
      <!-- Init colour -->

    <material name="dark">
    <color rgba="0.3 0.3 0.3 1.0"/>
    </material>

    <collision>
      <origin xyz="0.37369 0.0078 0.18386" rpy="0 0 0"/>
      <geometry>
        <cylinder length="0.0315" radius="0.055"/>
      </geometry>
    </collision>

    <inertial>
      <mass value="0.114" />
      <origin xyz="0 0 0" />
      <inertia ixx="0.001" ixy="0.0" ixz="0.0" iyy="0.001" iyz="0.0" izz="0.001" />
    </inertial>
  </link>

</robot>
